<?xml version="1.0" encoding="utf-8"?>
<!-- This URDF was automatically created by SolidWorks to URDF Exporter! Originally created by Stephen Brawner (brawner@gmail.com) 
     Commit Version: 1.6.0-4-g7f85cfe  Build Version: 1.6.7995.38578
     For more information, please see http://wiki.ros.org/sw_urdf_exporter -->
<robot
  name="tjurm_arm_won">
  <link
    name="base_link">
    <inertial>
      <origin
        xyz="0.00011022 0.00053417 0.012164"
        rpy="0 0 0" />
      <mass
        value="0.24508" />
      <inertia
        ixx="0.00014956"
        ixy="1.7088E-07"
        ixz="1.25E-09"
        iyy="0.00027306"
        iyz="5.4586E-08"
        izz="0.00041592" />
    </inertial>
    <visual>
      <origin
        xyz="0 0 0"
        rpy="0 0 0" />
      <geometry>
        <mesh
          filename="package://tjurm_arm_won/meshes/base_link.STL" />
      </geometry>
      <material
        name="">
        <color
          rgba="0.50196 0.50196 0.50196 1" />
      </material>
    </visual>
    <collision>
      <origin
        xyz="0 0 0"
        rpy="0 0 0" />
      <geometry>
        <mesh
          filename="package://tjurm_arm_won/meshes/base_link.STL" />
      </geometry>
    </collision>
  </link>
  <link
    name="link1">
    <inertial>
      <origin
        xyz="-0.0015821 -0.0046198 -0.046525"
        rpy="0 0 0" />
      <mass
        value="0.4841" />
      <inertia
        ixx="0.00043317"
        ixy="-3.8728E-08"
        ixz="-7.3882E-08"
        iyy="0.00053999"
        iyz="-1.9596E-07"
        izz="0.00062525" />
    </inertial>
    <visual>
      <origin
        xyz="0 0 0"
        rpy="0 0 0" />
      <geometry>
        <mesh
          filename="package://tjurm_arm_won/meshes/link1.STL" />
      </geometry>
      <material
        name="">
        <color
          rgba="1 1 1 1" />
      </material>
    </visual>
    <collision>
      <origin
        xyz="0 0 0"
        rpy="0 0 0" />
      <geometry>
        <mesh
          filename="package://tjurm_arm_won/meshes/link1.STL" />
      </geometry>
    </collision>
  </link>
  <joint
    name="joint1"
    type="revolute">
    <origin
      xyz="0 0 0.116"
      rpy="0 0 0.55928" />
    <parent
      link="base_link" />
    <child
      link="link1" />
    <axis
      xyz="0 0 1" />
    <limit
      lower="-3.14"
      upper="3.14"
      effort="100"
      velocity="1" />
  </joint>
  <link
    name="link2">
    <inertial>
      <origin
        xyz="0.036572 -0.088845 -0.0047651"
        rpy="0 0 0" />
      <mass
        value="0.96792" />
      <inertia
        ixx="0.0042639"
        ixy="0.0013774"
        ixz="-3.3091E-08"
        iyy="0.0012653"
        iyz="2.0765E-07"
        izz="0.0051304" />
    </inertial>
    <visual>
      <origin
        xyz="0 0 0"
        rpy="0 0 0" />
      <geometry>
        <mesh
          filename="package://tjurm_arm_won/meshes/link2.STL" />
      </geometry>
      <material
        name="">
        <color
          rgba="1 1 1 1" />
      </material>
    </visual>
    <collision>
      <origin
        xyz="0 0 0"
        rpy="0 0 0" />
      <geometry>
        <mesh
          filename="package://tjurm_arm_won/meshes/link2.STL" />
      </geometry>
    </collision>
  </link>
  <joint
    name="joint2"
    type="revolute">
    <origin
      xyz="0 0 0"
      rpy="-1.5708 0 0" />
    <parent
      link="link1" />
    <child
      link="link2" />
    <axis
      xyz="0 0 1" />
    <limit
      lower="-3.14"
      upper="3.14"
      effort="100"
      velocity="1" />
  </joint>
  <link
    name="link3">
    <inertial>
      <origin
        xyz="0.48342 0.20024 0.010212"
        rpy="0 0 0" />
      <mass
        value="33.889" />
      <inertia
        ixx="0.35951"
        ixy="-0.11908"
        ixz="9.1541E-08"
        iyy="0.46039"
        iyz="3.62E-07"
        izz="0.56671" />
    </inertial>
    <visual>
      <origin
        xyz="0 0 0"
        rpy="0 0 0" />
      <geometry>
        <mesh
          filename="package://tjurm_arm_won/meshes/link3.STL" />
      </geometry>
      <material
        name="">
        <color
          rgba="1 1 1 1" />
      </material>
    </visual>
    <collision>
      <origin
        xyz="0 0 0"
        rpy="0 0 0" />
      <geometry>
        <mesh
          filename="package://tjurm_arm_won/meshes/link3.STL" />
      </geometry>
    </collision>
  </link>
  <joint
    name="joint3"
    type="revolute">
    <origin
      xyz="0.10898 -0.2795 0"
      rpy="0 0 -1.5708" />
    <parent
      link="link2" />
    <child
      link="link3" />
    <axis
      xyz="0 0 1" />
    <limit
      lower="-3.14"
      upper="3.14"
      effort="100"
      velocity="1" />
  </joint>
  <link
    name="link4">
    <inertial>
      <origin
        xyz="0.010237 0.0017188 -0.14273"
        rpy="0 0 0" />
      <mass
        value="0.68146" />
      <inertia
        ixx="0.0014334"
        ixy="1.0724E-07"
        ixz="7.9375E-05"
        iyy="0.0014255"
        iyz="-2.4467E-07"
        izz="0.00033848" />
    </inertial>
    <visual>
      <origin
        xyz="0 0 0"
        rpy="0 0 0" />
      <geometry>
        <mesh
          filename="package://tjurm_arm_won/meshes/link4.STL" />
      </geometry>
      <material
        name="">
        <color
          rgba="1 1 1 1" />
      </material>
    </visual>
    <collision>
      <origin
        xyz="0 0 0"
        rpy="0 0 0" />
      <geometry>
        <mesh
          filename="package://tjurm_arm_won/meshes/link4.STL" />
      </geometry>
    </collision>
  </link>
  <joint
    name="joint4"
    type="revolute">
    <origin
      xyz="0.11398 0.39403 0"
      rpy="-1.5708 0 -0.19427" />
    <parent
      link="link3" />
    <child
      link="link4" />
    <axis
      xyz="0 0 1" />
    <limit
      lower="-3.14"
      upper="3.14"
      effort="100"
      velocity="1" />
  </joint>
  <link
    name="link5">
    <inertial>
      <origin
        xyz="2.931E-05 -0.0271 0.002163"
        rpy="0 0 0" />
      <mass
        value="0.29207" />
      <inertia
        ixx="7.0217E-05"
        ixy="-5.6893E-08"
        ixz="1.7329E-08"
        iyy="0.00011046"
        iyz="7.4078E-08"
        izz="6.7984E-05" />
    </inertial>
    <visual>
      <origin
        xyz="0 0 0"
        rpy="0 0 0" />
      <geometry>
        <mesh
          filename="package://tjurm_arm_won/meshes/link5.STL" />
      </geometry>
      <material
        name="">
        <color
          rgba="0.37255 0.37255 0.37255 1" />
      </material>
    </visual>
    <collision>
      <origin
        xyz="0 0 0"
        rpy="0 0 0" />
      <geometry>
        <mesh
          filename="package://tjurm_arm_won/meshes/link5.STL" />
      </geometry>
    </collision>
  </link>
  <joint
    name="joint5"
    type="revolute">
    <origin
      xyz="0 0 0"
      rpy="-1.5708 0 0" />
    <parent
      link="link4" />
    <child
      link="link5" />
    <axis
      xyz="0 0 1" />
    <limit
      lower="-3.14"
      upper="3.14"
      effort="100"
      velocity="1" />
  </joint>
  <link
    name="link6">
    <inertial>
      <origin
        xyz="0.0029253 4.8597E-05 0.11575"
        rpy="0 0 0" />
      <mass
        value="7.6366" />
      <inertia
        ixx="0.048445"
        ixy="-9.6208E-11"
        ixz="1.3674E-06"
        iyy="0.048461"
        iyz="-2.3383E-08"
        izz="0.048449" />
    </inertial>
    <visual>
      <origin
        xyz="0 0 0"
        rpy="0 0 0" />
      <geometry>
        <mesh
          filename="package://tjurm_arm_won/meshes/link6.STL" />
      </geometry>
      <material
        name="">
        <color
          rgba="1 1 1 1" />
      </material>
    </visual>
    <collision>
      <origin
        xyz="0 0 0"
        rpy="0 0 0" />
      <geometry>
        <mesh
          filename="package://tjurm_arm_won/meshes/link6.STL" />
      </geometry>
    </collision>
  </link>
  <joint
    name="joint6"
    type="revolute">
    <origin
      xyz="0 -0.042454 0"
      rpy="1.5708 0 0" />
    <parent
      link="link5" />
    <child
      link="link6" />
    <axis
      xyz="0 0 1" />
    <limit
      lower="-3.14"
      upper="3.14"
      effort="100"
      velocity="1" />
  </joint>
</robot>